# 三十、异常处理

PHP 5 引入了*异常*，这是一种内置机制，用于在程序失败发生的上下文中处理程序失败。与通常需要由开发人员修复的错误不同，异常由脚本处理。它们代表了一种不规则的运行时情况，这种情况应该是有可能发生的，并且脚本应该能够自己处理。

## Try-catch 语句

为了处理一个异常，必须使用一个`try-catch`语句来捕获它。该语句由一个包含可能导致异常的代码的`try`块和一个或多个`catch`子句组成。

```php
try
{
  $div = invert(0);
}
catch (LogicException $e) {}

```

如果`try`块成功执行，程序将在`try-catch`语句后继续运行。然而，如果出现异常，执行将传递给第一个能够处理该异常类型的`catch`块。

## 抛出异常

当出现函数无法恢复的情况时，它可以生成一个异常，通知调用者函数已经失败。这是通过使用关键字`throw`完成的，后跟一个新的类实例`Throwable`或者它的一个子类。在下面的例子中，抛出了`LogicException`类型。它继承自异常类，而异常类又继承自`Throwable`。<sup>T5 1T7】</sup>

```php
function invert($x)
{
  if ($x == 0) {
    throw new LogicException('Division by zero');
  }
  return 1 / $x;
}

```

## 捕捉块

在前面的例子中，`catch`块被设置为处理内置的`LogicException`类型。如果`try`块中的代码可以抛出更多种类的异常，那么可以使用多个`catch`块，允许以不同的方式处理不同的异常。

```php
catch (LogicException $e) {}
catch (RuntimeException $e) {}
// ...

```

为了捕捉更具体的异常，需要将`catch`块放在更一般的异常之前。比如`LogicException`继承自`Exception`，所以需要先抓。

```php
catch (LogicException $e) {}
catch (Exception $e) {}

```

`catch`子句可以定义一个异常对象。这个对象用于获取关于异常的更多信息，比如使用`getMessage`方法对异常的描述。

```php
catch (LogicException $e)
{
  echo $e->getMessage(); // "Division by zero"
}

```

从 PHP 8 开始，如果不需要使用异常对象，可以选择省略该对象。

```php
catch (LogicException) {}

```

## 最终阻止

PHP 5.5 引入了`finally`块，它可以作为`try-catch`语句的最后一个子句添加。该块用于清理`try`块中分配的资源。无论是否有异常，它总是会执行。

```php
$resource = myopen();
try { myuse($resource); }
catch(Exception $e) {}
finally { myfree($resource); }

```

## 再次引发异常

有时一个异常不能在第一次被捕获的地方被处理。然后可以使用关键字`throw`后跟异常对象来重新抛出它。

```php
try { $div = invert(0); }
catch (LogicException $e) { throw $e; }

```

然后，异常沿着调用方堆栈向上传播，直到被另一个`try-catch`语句捕获。如果异常从未被捕获，它将成为一个级别为`E_ERROR`的错误，这会暂停脚本，除非定义了一个未被捕获的异常处理程序。

PHP 8 把`throw`从语句变成了表达式。这使得在任何允许表达式的地方抛出异常成为可能，比如在下面的语句中。

```php
$name = $_GET['name'] ?? throw new Exception('name missing');

```

## 未捕获的异常处理程序

`set_exception_handler`函数允许捕获任何未被捕获的异常。它采用单个参数，即针对此类事件引发的回调函数。

```php
set_exception_handler('myException');

```

回调函数只需要一个参数，即抛出的异常对象。

```php
function myException($e)
{
  $file = 'exceptionlog.txt';
  file_put_contents($file, $e->getMessage(), FILE_APPEND);
  require_once('my_error_page.php');
  exit;
}

```

因为这个异常处理程序是在发生异常的上下文之外调用的，所以从异常中恢复会很困难。相反，此示例处理程序将异常写入日志文件并显示错误页面。为了停止脚本的进一步执行，使用了内置的`exit`构造。它与`die`构造同义，并且可以选择接受一个字符串参数，该参数在脚本暂停之前打印。

## 错误和异常

尽管抛出异常是为了由脚本处理，但会生成错误来通知开发人员代码中有错误。当涉及到运行时出现的问题时，异常机制通常被认为是优越的。然而，由于它直到 PHP 5 才被引入，所以直到 PHP 8，所有内部函数都继续使用错误机制。从 PHP 8 开始，许多错误被重新归类为`Error`异常。例如，在 PHP 8 中被零除会抛出一个`DivisionByZeroError`异常，而在以前的 PHP 版本中它会触发一个警告。

```php
try {
  echo 1/0; // throws exception in PHP 8
}
catch(DivisionByZeroError $e){
  echo $e->getMessage();
}

```

`Throwable`有两个内置子类，Exception 和`Error`。从 PHP 8 开始，大多数内部函数抛出`Error`类型的异常，比如`TypeError`、`ValueError`或`DivisionByZeroError`。

对于用户定义的函数，开发人员可以自由选择异常或错误处理机制，但更现代的异常机制是首选。请记住，错误不能被`try-catch`语句捕获。同样，异常不会触发错误处理程序。

<aside aria-label="Footnotes" class="FootnoteSection" epub:type="footnotes">Footnotes [1](#Fn1_source)

[T2`www.php.net/manual/en/spl.exceptions.php`](http://www.php.net/manual/en/spl.exceptions.php)

 </aside>